<?xml version="1.0" encoding="utf-8" ?>
<!-- =================================================================================== -->
<!-- |    This document was autogenerated by xacro from /home/nvidia/catkin_workspace/src/chin_arm/chin_crb7_description/urdf/chin_crb7.urdf.xacro | -->
<!-- |    EDITING THIS FILE BY HAND IS NOT RECOMMENDED                                 | -->
<!-- =================================================================================== -->
<robot name="chin_arm">
    <!--sub-link defining detailed meshes for collision with environment-->
    <link name="chin_link_0">
        <visual>
            <origin rpy="0 0 0" xyz="0 0 0" />
            <geometry>
                <mesh filename="package://chin_crb7_description/meshes/visual/link_0.dae" />
            </geometry>
        </visual>
        <collision>
            <origin rpy="0 0 0" xyz="0 0 0" />
            <geometry>
                <mesh filename="package://chin_crb7_description/meshes/collision/link_0.stl" />
            </geometry>
        </collision>
        <inertial>
            <mass value="0.1" />
            <origin xyz="0 0 0" rpy="0 0 0" />
            <inertia ixx="0.03" iyy="0.03" izz="0.03" ixy="0.0" ixz="0.0" iyz="0.0" />
        </inertial>
    </link>
    <!--sub-link defining detailed meshes for collision with environment-->
    <link name="chin_link_1">
        <visual>
            <origin rpy="0 0 0" xyz="0 0 0" />
            <geometry>
                <mesh filename="package://chin_crb7_description/meshes/visual/link_1.dae" />
            </geometry>
        </visual>
        <collision>
            <origin rpy="0 0 0" xyz="0 0 0" />
            <geometry>
                <mesh filename="package://chin_crb7_description/meshes/collision/link_1.stl" />
            </geometry>
        </collision>
        <inertial>
            <mass value="0.1" />
            <origin xyz="0 0 0" rpy="0 0 0" />
            <inertia ixx="0.03" iyy="0.03" izz="0.03" ixy="0.0" ixz="0.0" iyz="0.0" />
        </inertial>
    </link>
    <joint name="chin_joint_1" type="revolute">
        <safety_controller k_position="100.0" k_velocity="40.0" soft_lower_limit="-3.14159265359" soft_upper_limit="3.14159265359" />
        <origin rpy="0 0 0" xyz="0 0 0.2038" />
        <parent link="chin_link_0" />
        <child link="chin_link_1" />
        <axis xyz="0 0 1" />
        <limit effort="0" lower="-3.14159265359" upper="3.14159265359" velocity="0" />
        <dynamics D="1" K="7000" damping="0.003" friction="0.0" mu_coulomb="0" mu_viscous="16" />
    </joint>
    <!--sub-link defining detailed meshes for collision with environment-->
    <link name="chin_link_2">
        <visual>
            <origin rpy="0 0 0" xyz="0 0 0" />
            <geometry>
                <mesh filename="package://chin_crb7_description/meshes/visual/link_2.dae" />
            </geometry>
        </visual>
        <collision>
            <origin rpy="0 0 0" xyz="0 0 0" />
            <geometry>
                <mesh filename="package://chin_crb7_description/meshes/collision/link_2.stl" />
            </geometry>
        </collision>
        <inertial>
            <mass value="0.1" />
            <origin xyz="0 0 0" rpy="0 0 0" />
            <inertia ixx="0.03" iyy="0.03" izz="0.03" ixy="0.0" ixz="0.0" iyz="0.0" />
        </inertial>
    </link>
    <joint name="chin_joint_2" type="revolute">
        <safety_controller k_position="100.0" k_velocity="40.0" soft_lower_limit="-3.14159265359" soft_upper_limit="3.14159265359" />
        <origin rpy="-1.57079632679 0 0" xyz="0 0.082 0.081" />
        <parent link="chin_link_1" />
        <child link="chin_link_2" />
        <axis xyz="0 0 1" />
        <limit effort="0" lower="-3.14159265359" upper="3.14159265359" velocity="0" />
        <dynamics D="1" K="7000" damping="0.003" friction="0.0" mu_coulomb="0" mu_viscous="16" />
    </joint>
    <!--sub-link defining detailed meshes for collision with environment-->
    <link name="chin_link_3">
        <visual>
            <origin rpy="0 0 0" xyz="0 0 0" />
            <geometry>
                <mesh filename="package://chin_crb7_description/meshes/visual/link_3.dae" />
            </geometry>
        </visual>
        <collision>
            <origin rpy="0 0 0" xyz="0 0 0" />
            <geometry>
                <mesh filename="package://chin_crb7_description/meshes/collision/link_3.stl" />
            </geometry>
        </collision>
        <inertial>
            <mass value="0.1" />
            <origin xyz="0 0 0" rpy="0 0 0" />
            <inertia ixx="0.03" iyy="0.03" izz="0.03" ixy="0.0" ixz="0.0" iyz="0.0" />
        </inertial>
    </link>
    <joint name="chin_joint_3" type="revolute">
        <safety_controller k_position="100.0" k_velocity="40.0" soft_lower_limit="-2.79252680319" soft_upper_limit="2.79252680319" />
        <origin rpy="3.14159265359 0 0" xyz="0 -0.398 0" />
        <parent link="chin_link_2" />
        <child link="chin_link_3" />
        <axis xyz="0 0 1" />
        <limit effort="0" lower="-2.79252680319" upper="2.79252680319" velocity="0" />
        <dynamics D="1" K="7000" damping="0.003" friction="0.0" mu_coulomb="0" mu_viscous="16" />
    </joint>
    <!--sub-link defining detailed meshes for collision with environment-->
    <link name="chin_link_4">
        <visual>
            <origin rpy="0 0 0" xyz="0 0 0" />
            <geometry>
                <mesh filename="package://chin_crb7_description/meshes/visual/link_4.dae" />
            </geometry>
        </visual>
        <collision>
            <origin rpy="0 0 0" xyz="0 0 0" />
            <geometry>
                <mesh filename="package://chin_crb7_description/meshes/collision/link_4.stl" />
            </geometry>
        </collision>
        <inertial>
            <mass value="0.1" />
            <origin xyz="0 0 0" rpy="0 0 0" />
            <inertia ixx="0.03" iyy="0.03" izz="0.03" ixy="0.0" ixz="0.0" iyz="0.0" />
        </inertial>
    </link>
    <joint name="chin_joint_4" type="revolute">
        <safety_controller k_position="100.0" k_velocity="40.0" soft_lower_limit="-3.14159265359" soft_upper_limit="3.14159265359" />
        <origin rpy="3.14159265359 0 0" xyz="0 0.36 -0.02" />
        <parent link="chin_link_3" />
        <child link="chin_link_4" />
        <axis xyz="0 0 1" />
        <limit effort="0" lower="-3.14159265359" upper="3.14159265359" velocity="0" />
        <dynamics D="1" K="7000" damping="0.003" friction="0.0" mu_coulomb="0" mu_viscous="16" />
    </joint>
    <!--sub-link defining detailed meshes for collision with environment-->
    <link name="chin_link_5">
        <visual>
            <origin rpy="0 0 0" xyz="0 0 0" />
            <geometry>
                <mesh filename="package://chin_crb7_description/meshes/visual/link_5.dae" />
            </geometry>
        </visual>
        <collision>
            <origin rpy="0 0 0" xyz="0 0 0" />
            <geometry>
                <mesh filename="package://chin_crb7_description/meshes/collision/link_5.stl" />
            </geometry>
        </collision>
        <inertial>
            <mass value="0.1" />
            <origin xyz="0 0 0" rpy="0 0 0" />
            <inertia ixx="0.03" iyy="0.03" izz="0.03" ixy="0.0" ixz="0.0" iyz="0.0" />
        </inertial>
    </link>
    <joint name="chin_joint_5" type="revolute">
        <safety_controller k_position="100.0" k_velocity="40.0" soft_lower_limit="-3.14159265359" soft_upper_limit="3.14159265359" />
        <origin rpy="1.57079632679 0 0" xyz="0 -0.083 0.087" />
        <parent link="chin_link_4" />
        <child link="chin_link_5" />
        <axis xyz="0 0 1" />
        <limit effort="0" lower="-3.14159265359" upper="3.14159265359" velocity="0" />
        <dynamics D="1" K="7000" damping="0.003" friction="0.0" mu_coulomb="0" mu_viscous="16" />
    </joint>
    <!--sub-link defining detailed meshes for collision with environment-->
    <link name="chin_link_6">
        <visual>
            <origin rpy="0 0 0" xyz="0 0 0" />
            <geometry>
                <mesh filename="package://chin_crb7_description/meshes/visual/link_6.dae" />
            </geometry>
        </visual>
        <collision>
            <origin rpy="0 0 0" xyz="0 0 0" />
            <geometry>
                <mesh filename="package://chin_crb7_description/meshes/collision/link_6.stl" />
            </geometry>
        </collision>
        <inertial>
            <mass value="0.1" />
            <origin xyz="0 0 0" rpy="0 0 0" />
            <inertia ixx="0.03" iyy="0.03" izz="0.03" ixy="0.0" ixz="0.0" iyz="0.0" />
        </inertial>
    </link>
    <joint name="chin_joint_6" type="revolute">
        <safety_controller k_position="100.0" k_velocity="40.0" soft_lower_limit="-3.14159265359" soft_upper_limit="3.14159265359" />
        <origin rpy="-1.57079632679 0 0" xyz="0 0.083 0.087" />
        <parent link="chin_link_5" />
        <child link="chin_link_6" />
        <axis xyz="0 0 1" />
        <limit effort="0" lower="-3.14159265359" upper="3.14159265359" velocity="0" />
        <dynamics D="1" K="7000" damping="0.003" friction="0.0" mu_coulomb="0" mu_viscous="16" />
    </joint>
    <!--link7 to link6-->
    <link name="chin_link_7" />
    <joint name="chin_joint_7" type="fixed">
        <origin rpy="0 0 -3.14159265359" xyz="0 0 0.077" />
        <parent link="chin_link_6" />
        <child link="chin_link_7" />
    </joint>
    <transmission name="trans_chin_joint_1">
        <type>transmission_interface/SimpleTransmission</type>
        <joint name="chin_joint_1">
            <hardwareInterface>hardware_interface/PositionJointInterface</hardwareInterface>
        </joint>
        <actuator name="chin_joint_1_motor">
            <hardwareInterface>hardware_interface/PositionJointInterface</hardwareInterface>
            <mechanicalReduction>1</mechanicalReduction>
        </actuator>
    </transmission>
    <transmission name="trans_chin_joint_2">
        <type>transmission_interface/SimpleTransmission</type>
        <joint name="chin_joint_2">
            <hardwareInterface>hardware_interface/PositionJointInterface</hardwareInterface>
        </joint>
        <actuator name="chin_joint_2_motor">
            <hardwareInterface>hardware_interface/PositionJointInterface</hardwareInterface>
            <mechanicalReduction>1</mechanicalReduction>
        </actuator>
    </transmission>
    <transmission name="trans_chin_joint_3">
        <type>transmission_interface/SimpleTransmission</type>
        <joint name="chin_joint_3">
            <hardwareInterface>hardware_interface/PositionJointInterface</hardwareInterface>
        </joint>
        <actuator name="chin_joint_3_motor">
            <hardwareInterface>hardware_interface/PositionJointInterface</hardwareInterface>
            <mechanicalReduction>1</mechanicalReduction>
        </actuator>
    </transmission>
    <transmission name="trans_chin_joint_4">
        <type>transmission_interface/SimpleTransmission</type>
        <joint name="chin_joint_4">
            <hardwareInterface>hardware_interface/PositionJointInterface</hardwareInterface>
        </joint>
        <actuator name="chin_joint_4_motor">
            <hardwareInterface>hardware_interface/PositionJointInterface</hardwareInterface>
            <mechanicalReduction>1</mechanicalReduction>
        </actuator>
    </transmission>
    <transmission name="trans_chin_joint_5">
        <type>transmission_interface/SimpleTransmission</type>
        <joint name="chin_joint_5">
            <hardwareInterface>hardware_interface/PositionJointInterface</hardwareInterface>
        </joint>
        <actuator name="chin_joint_5_motor">
            <hardwareInterface>hardware_interface/PositionJointInterface</hardwareInterface>
            <mechanicalReduction>1</mechanicalReduction>
        </actuator>
    </transmission>
    <transmission name="trans_chin_joint_6">
        <type>transmission_interface/SimpleTransmission</type>
        <joint name="chin_joint_6">
            <hardwareInterface>hardware_interface/PositionJointInterface</hardwareInterface>
        </joint>
        <actuator name="chin_joint_6_motor">
            <hardwareInterface>hardware_interface/PositionJointInterface</hardwareInterface>
            <mechanicalReduction>1</mechanicalReduction>
        </actuator>
    </transmission>
    <gazebo>
        <plugin name="gazebo_ros_control">
            <robotNamespace>/</robotNamespace>
        </plugin>
    </gazebo>
</robot>

