<?xml version="1.0" encoding="utf-8" ?>
<!-- =================================================================================== -->
<!-- |    This document was autogenerated by xacro from /home/nvidia/catkin_workspace/src/chin_arm/chin_description/urdf/chin_arm_frame.urdf.xacro | -->
<!-- |    EDITING THIS FILE BY HAND IS NOT RECOMMENDED                                 | -->
<!-- =================================================================================== -->
<robot name="chin_arm">
    <material name="white">
        <color rgba="1 1 1 1" />
    </material>
    <material name="blue">
        <color rgba="0 0 0.8 1" />
    </material>
    <material name="silver">
        <color rgba="0.51 0.54 0.59 1" />
    </material>
    <!--sub-link defining detailed meshes for collision with environment-->
    <link name="chin_link_0">
        <visual>
            <origin rpy="0 0 0" xyz="0 0 0.102" />
            <geometry>
                <cylinder length="0.204" radius="0.095" />
            </geometry>
            <material name="black" />
        </visual>
        <collision>
            <origin rpy="0 0 0" xyz="0 0 0.102" />
            <geometry>
                <cylinder length="0.204" radius="0.095" />
            </geometry>
        </collision>
        <inertial>
            <mass value="0.1" />
            <origin xyz="0 0 0" rpy="0 0 0" />
            <inertia ixx="0.03" iyy="0.03" izz="0.03" ixy="0.0" ixz="0.0" iyz="0.0" />
        </inertial>
    </link>
    <!--sub-link defining coarse geometries of real robot's internal self-collision-->
    <link name="chin_link_0_sc" />
    <!--fixed joint between both sub-links-->
    <joint name="chin_link_0_sc_joint" type="fixed">
        <origin rpy="0 0 0" />
        <parent link="chin_link_0" />
        <child link="chin_link_0_sc" />
    </joint>
    <!--sub-link defining detailed meshes for collision with environment-->
    <link name="chin_link_1">
        <visual>
            <origin rpy="0 0 0" xyz="0 0 0.0405" />
            <geometry>
                <cylinder length="0.081" radius="0.066" />
            </geometry>
            <material name="silver" />
        </visual>
        <collision>
            <origin rpy="0 0 0" xyz="0 0 0.0405" />
            <geometry>
                <cylinder length="0.081" radius="0.066" />
            </geometry>
        </collision>
        <inertial>
            <mass value="0.1" />
            <origin xyz="0 0 0" rpy="0 0 0" />
            <inertia ixx="0.03" iyy="0.03" izz="0.03" ixy="0.0" ixz="0.0" iyz="0.0" />
        </inertial>
    </link>
    <!--sub-link defining coarse geometries of real robot's internal self-collision-->
    <link name="chin_link_1_sc">
        <collision>
            <origin rpy="0 0 0" xyz="0 0 0.0405" />
            <geometry>
                <cylinder length="0.081" radius="0.066" />
            </geometry>
        </collision>
        <collision>
            <origin xyz="0 0 0.081" />
            <geometry>
                <sphere radius="0.066" />
            </geometry>
        </collision>
        <collision>
            <origin xyz="0 0 0.0" />
            <geometry>
                <sphere radius="0.066" />
            </geometry>
        </collision>
        <inertial>
            <mass value="0.1" />
            <origin xyz="0 0 0" rpy="0 0 0" />
            <inertia ixx="0.03" iyy="0.03" izz="0.03" ixy="0.0" ixz="0.0" iyz="0.0" />
        </inertial>
    </link>
    <!--fixed joint between both sub-links-->
    <joint name="chin_link_1_sc_joint" type="fixed">
        <origin rpy="0 0 0" />
        <parent link="chin_link_1" />
        <child link="chin_link_1_sc" />
    </joint>
    <joint name="chin_joint_1" type="revolute">
        <safety_controller k_position="100.0" k_velocity="40.0" soft_lower_limit="-3.14159265359" soft_upper_limit="3.14159265359" />
        <origin rpy="0 0 0" xyz="0 0 0.204" />
        <parent link="chin_link_0" />
        <child link="chin_link_1" />
        <axis xyz="0 0 1" />
        <limit effort="0" lower="-3.14159265359" upper="3.14159265359" velocity="0" />
        <dynamics D="1" K="7000" damping="0.003" friction="0.0" mu_coulomb="0" mu_viscous="16" />
    </joint>
    <!--sub-link defining detailed meshes for collision with environment-->
    <link name="chin_link_2">
        <visual>
            <origin rpy="0 0 0" xyz="0 0 0.041" />
            <geometry>
                <cylinder length="0.082" radius="0.066" />
            </geometry>
            <material name="white" />
        </visual>
        <collision>
            <origin rpy="0 0 0" xyz="0 0 0.041" />
            <geometry>
                <cylinder length="0.082" radius="0.066" />
            </geometry>
        </collision>
        <inertial>
            <mass value="0.1" />
            <origin xyz="0 0 0" rpy="0 0 0" />
            <inertia ixx="0.03" iyy="0.03" izz="0.03" ixy="0.0" ixz="0.0" iyz="0.0" />
        </inertial>
    </link>
    <!--sub-link defining coarse geometries of real robot's internal self-collision-->
    <link name="chin_link_2_sc">
        <collision>
            <origin rpy="0 0 0" xyz="0 0 0.041" />
            <geometry>
                <cylinder length="0.082" radius="0.066" />
            </geometry>
        </collision>
        <collision>
            <origin xyz="0 0 0.082" />
            <geometry>
                <sphere radius="0.066" />
            </geometry>
        </collision>
        <collision>
            <origin xyz="0 0 0.0" />
            <geometry>
                <sphere radius="0.066" />
            </geometry>
        </collision>
        <inertial>
            <mass value="0.1" />
            <origin xyz="0 0 0" rpy="0 0 0" />
            <inertia ixx="0.03" iyy="0.03" izz="0.03" ixy="0.0" ixz="0.0" iyz="0.0" />
        </inertial>
    </link>
    <!--fixed joint between both sub-links-->
    <joint name="chin_link_2_sc_joint" type="fixed">
        <origin rpy="0 0 0" />
        <parent link="chin_link_2" />
        <child link="chin_link_2_sc" />
    </joint>
    <joint name="chin_joint_2" type="fixed">
        <origin rpy="-1.57079632679 0 0" xyz="0 0 0.081" />
        <parent link="chin_link_1" />
        <child link="chin_link_2" />
        <axis xyz="0 0 1" />
        <dynamics D="1" K="7000" damping="0.003" friction="0.0" mu_coulomb="0" mu_viscous="16" />
    </joint>
    <!--sub-link defining detailed meshes for collision with environment-->
    <link name="chin_link_3">
        <visual>
            <origin rpy="0 0 0" xyz="0 0 0.035" />
            <geometry>
                <cylinder length="0.07" radius="0.066" />
            </geometry>
            <material name="silver" />
        </visual>
        <collision>
            <origin rpy="0 0 0" xyz="0 0 0.035" />
            <geometry>
                <cylinder length="0.07" radius="0.066" />
            </geometry>
        </collision>
        <inertial>
            <mass value="0.1" />
            <origin xyz="0 0 0" rpy="0 0 0" />
            <inertia ixx="0.03" iyy="0.03" izz="0.03" ixy="0.0" ixz="0.0" iyz="0.0" />
        </inertial>
    </link>
    <!--sub-link defining coarse geometries of real robot's internal self-collision-->
    <link name="chin_link_3_sc">
        <collision>
            <origin rpy="0 0 0" xyz="0 0 0.035" />
            <geometry>
                <cylinder length="0.07" radius="0.066" />
            </geometry>
        </collision>
        <collision>
            <origin xyz="0 0 0.07" />
            <geometry>
                <sphere radius="0.066" />
            </geometry>
        </collision>
        <collision>
            <origin xyz="0 0 0.0" />
            <geometry>
                <sphere radius="0.066" />
            </geometry>
        </collision>
        <inertial>
            <mass value="0.1" />
            <origin xyz="0 0 0" rpy="0 0 0" />
            <inertia ixx="0.03" iyy="0.03" izz="0.03" ixy="0.0" ixz="0.0" iyz="0.0" />
        </inertial>
    </link>
    <!--fixed joint between both sub-links-->
    <joint name="chin_link_3_sc_joint" type="fixed">
        <origin rpy="0 0 0" />
        <parent link="chin_link_3" />
        <child link="chin_link_3_sc" />
    </joint>
    <joint name="chin_joint_3" type="revolute">
        <safety_controller k_position="100.0" k_velocity="40.0" soft_lower_limit="-3.14159265359" soft_upper_limit="3.14159265359" />
        <origin rpy="0 0 0" xyz="0 0 0.082" />
        <parent link="chin_link_2" />
        <child link="chin_link_3" />
        <axis xyz="0 0 1" />
        <limit effort="0" lower="-3.14159265359" upper="3.14159265359" velocity="0" />
        <dynamics D="1" K="7000" damping="0.003" friction="0.0" mu_coulomb="0" mu_viscous="16" />
    </joint>
    <!--sub-link defining detailed meshes for collision with environment-->
    <link name="chin_link_4">
        <visual>
            <origin rpy="0 0 0" xyz="0 0 0.199" />
            <geometry>
                <cylinder length="0.398" radius="0.055" />
            </geometry>
            <material name="white" />
        </visual>
        <collision>
            <origin rpy="0 0 0" xyz="0 0 0.199" />
            <geometry>
                <cylinder length="0.398" radius="0.055" />
            </geometry>
        </collision>
        <inertial>
            <mass value="0.1" />
            <origin xyz="0 0 0" rpy="0 0 0" />
            <inertia ixx="0.03" iyy="0.03" izz="0.03" ixy="0.0" ixz="0.0" iyz="0.0" />
        </inertial>
    </link>
    <!--sub-link defining coarse geometries of real robot's internal self-collision-->
    <link name="chin_link_4_sc">
        <collision>
            <origin rpy="0 0 0" xyz="0 0 0.199" />
            <geometry>
                <cylinder length="0.398" radius="0.055" />
            </geometry>
        </collision>
        <collision>
            <origin xyz="0 0 0.398" />
            <geometry>
                <sphere radius="0.055" />
            </geometry>
        </collision>
        <collision>
            <origin xyz="0 0 0.0" />
            <geometry>
                <sphere radius="0.055" />
            </geometry>
        </collision>
        <inertial>
            <mass value="0.1" />
            <origin xyz="0 0 0" rpy="0 0 0" />
            <inertia ixx="0.03" iyy="0.03" izz="0.03" ixy="0.0" ixz="0.0" iyz="0.0" />
        </inertial>
    </link>
    <!--fixed joint between both sub-links-->
    <joint name="chin_link_4_sc_joint" type="fixed">
        <origin rpy="0 0 0" />
        <parent link="chin_link_4" />
        <child link="chin_link_4_sc" />
    </joint>
    <joint name="chin_joint_4" type="fixed">
        <origin rpy="1.57079632679 0 0" xyz="0 0 0.07" />
        <parent link="chin_link_3" />
        <child link="chin_link_4" />
        <axis xyz="0 0 1" />
        <dynamics D="1" K="7000" damping="0.003" friction="0.0" mu_coulomb="0" mu_viscous="16" />
    </joint>
    <!--sub-link defining detailed meshes for collision with environment-->
    <link name="chin_link_5">
        <visual>
            <origin rpy="0 0 0" xyz="0 0 0.0325" />
            <geometry>
                <cylinder length="0.065" radius="0.055" />
            </geometry>
            <material name="white" />
        </visual>
        <collision>
            <origin rpy="0 0 0" xyz="0 0 0.0325" />
            <geometry>
                <cylinder length="0.065" radius="0.055" />
            </geometry>
        </collision>
        <inertial>
            <mass value="0.1" />
            <origin xyz="0 0 0" rpy="0 0 0" />
            <inertia ixx="0.03" iyy="0.03" izz="0.03" ixy="0.0" ixz="0.0" iyz="0.0" />
        </inertial>
    </link>
    <!--sub-link defining coarse geometries of real robot's internal self-collision-->
    <link name="chin_link_5_sc">
        <collision>
            <origin rpy="0 0 0" xyz="0 0 0.0325" />
            <geometry>
                <cylinder length="0.065" radius="0.055" />
            </geometry>
        </collision>
        <collision>
            <origin xyz="0 0 0.065" />
            <geometry>
                <sphere radius="0.055" />
            </geometry>
        </collision>
        <collision>
            <origin xyz="0 0 0.0" />
            <geometry>
                <sphere radius="0.055" />
            </geometry>
        </collision>
        <inertial>
            <mass value="0.1" />
            <origin xyz="0 0 0" rpy="0 0 0" />
            <inertia ixx="0.03" iyy="0.03" izz="0.03" ixy="0.0" ixz="0.0" iyz="0.0" />
        </inertial>
    </link>
    <!--fixed joint between both sub-links-->
    <joint name="chin_link_5_sc_joint" type="fixed">
        <origin rpy="0 0 0" />
        <parent link="chin_link_5" />
        <child link="chin_link_5_sc" />
    </joint>
    <joint name="chin_joint_5" type="fixed">
        <origin rpy="1.57079632679 0 0" xyz="0 0 0.398" />
        <parent link="chin_link_4" />
        <child link="chin_link_5" />
        <axis xyz="0 0 1" />
        <dynamics D="1" K="7000" damping="0.003" friction="0.0" mu_coulomb="0" mu_viscous="16" />
    </joint>
    <!--sub-link defining detailed meshes for collision with environment-->
    <link name="chin_link_6">
        <visual>
            <origin rpy="0 0 0" xyz="0 0 0.0315" />
            <geometry>
                <cylinder length="0.063" radius="0.055" />
            </geometry>
            <material name="silver" />
        </visual>
        <collision>
            <origin rpy="0 0 0" xyz="0 0 0.0315" />
            <geometry>
                <cylinder length="0.063" radius="0.055" />
            </geometry>
        </collision>
        <inertial>
            <mass value="0.1" />
            <origin xyz="0 0 0" rpy="0 0 0" />
            <inertia ixx="0.03" iyy="0.03" izz="0.03" ixy="0.0" ixz="0.0" iyz="0.0" />
        </inertial>
    </link>
    <!--sub-link defining coarse geometries of real robot's internal self-collision-->
    <link name="chin_link_6_sc">
        <collision>
            <origin rpy="0 0 0" xyz="0 0 0.0315" />
            <geometry>
                <cylinder length="0.063" radius="0.055" />
            </geometry>
        </collision>
        <collision>
            <origin xyz="0 0 0.063" />
            <geometry>
                <sphere radius="0.055" />
            </geometry>
        </collision>
        <collision>
            <origin xyz="0 0 0.0" />
            <geometry>
                <sphere radius="0.055" />
            </geometry>
        </collision>
        <inertial>
            <mass value="0.1" />
            <origin xyz="0 0 0" rpy="0 0 0" />
            <inertia ixx="0.03" iyy="0.03" izz="0.03" ixy="0.0" ixz="0.0" iyz="0.0" />
        </inertial>
    </link>
    <!--fixed joint between both sub-links-->
    <joint name="chin_link_6_sc_joint" type="fixed">
        <origin rpy="0 0 0" />
        <parent link="chin_link_6" />
        <child link="chin_link_6_sc" />
    </joint>
    <joint name="chin_joint_6" type="revolute">
        <safety_controller k_position="100.0" k_velocity="40.0" soft_lower_limit="-2.7925" soft_upper_limit="2.7925" />
        <origin rpy="0 0 0" xyz="0 0 0.065" />
        <parent link="chin_link_5" />
        <child link="chin_link_6" />
        <axis xyz="0 0 1" />
        <limit effort="0" lower="-2.7925" upper="2.7925" velocity="0" />
        <dynamics D="1" K="7000" damping="0.003" friction="0.0" mu_coulomb="0" mu_viscous="16" />
    </joint>
    <!--sub-link defining detailed meshes for collision with environment-->
    <link name="chin_link_7">
        <visual>
            <origin rpy="0 0 0" xyz="0 0 0.18" />
            <geometry>
                <cylinder length="0.36" radius="0.045" />
            </geometry>
            <material name="white" />
        </visual>
        <collision>
            <origin rpy="0 0 0" xyz="0 0 0.18" />
            <geometry>
                <cylinder length="0.36" radius="0.045" />
            </geometry>
        </collision>
        <inertial>
            <mass value="0.1" />
            <origin xyz="0 0 0" rpy="0 0 0" />
            <inertia ixx="0.03" iyy="0.03" izz="0.03" ixy="0.0" ixz="0.0" iyz="0.0" />
        </inertial>
    </link>
    <!--sub-link defining coarse geometries of real robot's internal self-collision-->
    <link name="chin_link_7_sc">
        <collision>
            <origin rpy="0 0 0" xyz="0 0 0.18" />
            <geometry>
                <cylinder length="0.36" radius="0.045" />
            </geometry>
        </collision>
        <collision>
            <origin xyz="0 0 0.36" />
            <geometry>
                <sphere radius="0.045" />
            </geometry>
        </collision>
        <collision>
            <origin xyz="0 0 0.0" />
            <geometry>
                <sphere radius="0.045" />
            </geometry>
        </collision>
        <inertial>
            <mass value="0.1" />
            <origin xyz="0 0 0" rpy="0 0 0" />
            <inertia ixx="0.03" iyy="0.03" izz="0.03" ixy="0.0" ixz="0.0" iyz="0.0" />
        </inertial>
    </link>
    <!--fixed joint between both sub-links-->
    <joint name="chin_link_7_sc_joint" type="fixed">
        <origin rpy="0 0 0" />
        <parent link="chin_link_7" />
        <child link="chin_link_7_sc" />
    </joint>
    <joint name="chin_joint_7" type="fixed">
        <origin rpy="-1.57079632679 0 0" xyz="0 0 0.063" />
        <parent link="chin_link_6" />
        <child link="chin_link_7" />
        <axis xyz="0 0 1" />
        <dynamics D="1" K="7000" damping="0.003" friction="0.0" mu_coulomb="0" mu_viscous="16" />
    </joint>
    <!--sub-link defining detailed meshes for collision with environment-->
    <link name="chin_link_8">
        <visual>
            <origin rpy="0 0 0" xyz="0 0 0.0415" />
            <geometry>
                <cylinder length="0.083" radius="0.045" />
            </geometry>
            <material name="white" />
        </visual>
        <collision>
            <origin rpy="0 0 0" xyz="0 0 0.0415" />
            <geometry>
                <cylinder length="0.083" radius="0.045" />
            </geometry>
        </collision>
        <inertial>
            <mass value="0.1" />
            <origin xyz="0 0 0" rpy="0 0 0" />
            <inertia ixx="0.03" iyy="0.03" izz="0.03" ixy="0.0" ixz="0.0" iyz="0.0" />
        </inertial>
    </link>
    <!--sub-link defining coarse geometries of real robot's internal self-collision-->
    <link name="chin_link_8_sc">
        <collision>
            <origin rpy="0 0 0" xyz="0 0 0.0415" />
            <geometry>
                <cylinder length="0.083" radius="0.045" />
            </geometry>
        </collision>
        <collision>
            <origin xyz="0 0 0.083" />
            <geometry>
                <sphere radius="0.045" />
            </geometry>
        </collision>
        <collision>
            <origin xyz="0 0 0.0" />
            <geometry>
                <sphere radius="0.045" />
            </geometry>
        </collision>
        <inertial>
            <mass value="0.1" />
            <origin xyz="0 0 0" rpy="0 0 0" />
            <inertia ixx="0.03" iyy="0.03" izz="0.03" ixy="0.0" ixz="0.0" iyz="0.0" />
        </inertial>
    </link>
    <!--fixed joint between both sub-links-->
    <joint name="chin_link_8_sc_joint" type="fixed">
        <origin rpy="0 0 0" />
        <parent link="chin_link_8" />
        <child link="chin_link_8_sc" />
    </joint>
    <joint name="chin_joint_8" type="fixed">
        <origin rpy="-1.57079632679 0 0" xyz="0 0 0.36" />
        <parent link="chin_link_7" />
        <child link="chin_link_8" />
        <axis xyz="0 0 1" />
        <dynamics D="1" K="7000" damping="0.003" friction="0.0" mu_coulomb="0" mu_viscous="16" />
    </joint>
    <!--sub-link defining detailed meshes for collision with environment-->
    <link name="chin_link_9">
        <visual>
            <origin rpy="0 0 0" xyz="0 0 0.0435" />
            <geometry>
                <cylinder length="0.087" radius="0.045" />
            </geometry>
            <material name="silver" />
        </visual>
        <collision>
            <origin rpy="0 0 0" xyz="0 0 0.0435" />
            <geometry>
                <cylinder length="0.087" radius="0.045" />
            </geometry>
        </collision>
        <inertial>
            <mass value="0.1" />
            <origin xyz="0 0 0" rpy="0 0 0" />
            <inertia ixx="0.03" iyy="0.03" izz="0.03" ixy="0.0" ixz="0.0" iyz="0.0" />
        </inertial>
    </link>
    <!--sub-link defining coarse geometries of real robot's internal self-collision-->
    <link name="chin_link_9_sc">
        <collision>
            <origin rpy="0 0 0" xyz="0 0 0.0435" />
            <geometry>
                <cylinder length="0.087" radius="0.045" />
            </geometry>
        </collision>
        <collision>
            <origin xyz="0 0 0.087" />
            <geometry>
                <sphere radius="0.045" />
            </geometry>
        </collision>
        <collision>
            <origin xyz="0 0 0.0" />
            <geometry>
                <sphere radius="0.045" />
            </geometry>
        </collision>
        <inertial>
            <mass value="0.1" />
            <origin xyz="0 0 0" rpy="0 0 0" />
            <inertia ixx="0.03" iyy="0.03" izz="0.03" ixy="0.0" ixz="0.0" iyz="0.0" />
        </inertial>
    </link>
    <!--fixed joint between both sub-links-->
    <joint name="chin_link_9_sc_joint" type="fixed">
        <origin rpy="0 0 0" />
        <parent link="chin_link_9" />
        <child link="chin_link_9_sc" />
    </joint>
    <joint name="chin_joint_9" type="revolute">
        <safety_controller k_position="100.0" k_velocity="40.0" soft_lower_limit="-3.14159265359" soft_upper_limit="3.14159265359" />
        <origin rpy="0 0 0" xyz="0 0 0.083" />
        <parent link="chin_link_8" />
        <child link="chin_link_9" />
        <axis xyz="0 0 1" />
        <limit effort="0" lower="-3.14159265359" upper="3.14159265359" velocity="0" />
        <dynamics D="1" K="7000" damping="0.003" friction="0.0" mu_coulomb="0" mu_viscous="16" />
    </joint>
    <!--sub-link defining detailed meshes for collision with environment-->
    <link name="chin_link_10">
        <visual>
            <origin rpy="0 0 0" xyz="0 0 0.0415" />
            <geometry>
                <cylinder length="0.083" radius="0.045" />
            </geometry>
            <material name="white" />
        </visual>
        <collision>
            <origin rpy="0 0 0" xyz="0 0 0.0415" />
            <geometry>
                <cylinder length="0.083" radius="0.045" />
            </geometry>
        </collision>
        <inertial>
            <mass value="0.1" />
            <origin xyz="0 0 0" rpy="0 0 0" />
            <inertia ixx="0.03" iyy="0.03" izz="0.03" ixy="0.0" ixz="0.0" iyz="0.0" />
        </inertial>
    </link>
    <!--sub-link defining coarse geometries of real robot's internal self-collision-->
    <link name="chin_link_10_sc">
        <collision>
            <origin rpy="0 0 0" xyz="0 0 0.0415" />
            <geometry>
                <cylinder length="0.083" radius="0.045" />
            </geometry>
        </collision>
        <collision>
            <origin xyz="0 0 0.083" />
            <geometry>
                <sphere radius="0.045" />
            </geometry>
        </collision>
        <collision>
            <origin xyz="0 0 0.0" />
            <geometry>
                <sphere radius="0.045" />
            </geometry>
        </collision>
        <inertial>
            <mass value="0.1" />
            <origin xyz="0 0 0" rpy="0 0 0" />
            <inertia ixx="0.03" iyy="0.03" izz="0.03" ixy="0.0" ixz="0.0" iyz="0.0" />
        </inertial>
    </link>
    <!--fixed joint between both sub-links-->
    <joint name="chin_link_10_sc_joint" type="fixed">
        <origin rpy="0 0 0" />
        <parent link="chin_link_10" />
        <child link="chin_link_10_sc" />
    </joint>
    <joint name="chin_joint_10" type="fixed">
        <origin rpy="1.57079632679 0 0" xyz="0 0 0.087" />
        <parent link="chin_link_9" />
        <child link="chin_link_10" />
        <axis xyz="0 0 1" />
        <dynamics D="1" K="7000" damping="0.003" friction="0.0" mu_coulomb="0" mu_viscous="16" />
    </joint>
    <!--sub-link defining detailed meshes for collision with environment-->
    <link name="chin_link_11">
        <visual>
            <origin rpy="0 0 0" xyz="0 0 0.0435" />
            <geometry>
                <cylinder length="0.087" radius="0.045" />
            </geometry>
            <material name="silver" />
        </visual>
        <collision>
            <origin rpy="0 0 0" xyz="0 0 0.0435" />
            <geometry>
                <cylinder length="0.087" radius="0.045" />
            </geometry>
        </collision>
        <inertial>
            <mass value="0.1" />
            <origin xyz="0 0 0" rpy="0 0 0" />
            <inertia ixx="0.03" iyy="0.03" izz="0.03" ixy="0.0" ixz="0.0" iyz="0.0" />
        </inertial>
    </link>
    <!--sub-link defining coarse geometries of real robot's internal self-collision-->
    <link name="chin_link_11_sc">
        <collision>
            <origin rpy="0 0 0" xyz="0 0 0.0435" />
            <geometry>
                <cylinder length="0.087" radius="0.045" />
            </geometry>
        </collision>
        <collision>
            <origin xyz="0 0 0.087" />
            <geometry>
                <sphere radius="0.045" />
            </geometry>
        </collision>
        <collision>
            <origin xyz="0 0 0.0" />
            <geometry>
                <sphere radius="0.045" />
            </geometry>
        </collision>
        <inertial>
            <mass value="0.1" />
            <origin xyz="0 0 0" rpy="0 0 0" />
            <inertia ixx="0.03" iyy="0.03" izz="0.03" ixy="0.0" ixz="0.0" iyz="0.0" />
        </inertial>
    </link>
    <!--fixed joint between both sub-links-->
    <joint name="chin_link_11_sc_joint" type="fixed">
        <origin rpy="0 0 0" />
        <parent link="chin_link_11" />
        <child link="chin_link_11_sc" />
    </joint>
    <joint name="chin_joint_11" type="revolute">
        <safety_controller k_position="100.0" k_velocity="40.0" soft_lower_limit="-3.14159265359" soft_upper_limit="3.14159265359" />
        <origin rpy="0 0 0" xyz="0 0 0.083" />
        <parent link="chin_link_10" />
        <child link="chin_link_11" />
        <axis xyz="0 0 1" />
        <limit effort="0" lower="-3.14159265359" upper="3.14159265359" velocity="0" />
        <dynamics D="1" K="7000" damping="0.003" friction="0.0" mu_coulomb="0" mu_viscous="16" />
    </joint>
    <!--sub-link defining detailed meshes for collision with environment-->
    <link name="chin_link_12">
        <visual>
            <origin rpy="0 0 0" xyz="0 0 0.0415" />
            <geometry>
                <cylinder length="0.083" radius="0.045" />
            </geometry>
            <material name="white" />
        </visual>
        <collision>
            <origin rpy="0 0 0" xyz="0 0 0.0415" />
            <geometry>
                <cylinder length="0.083" radius="0.045" />
            </geometry>
        </collision>
        <inertial>
            <mass value="0.1" />
            <origin xyz="0 0 0" rpy="0 0 0" />
            <inertia ixx="0.03" iyy="0.03" izz="0.03" ixy="0.0" ixz="0.0" iyz="0.0" />
        </inertial>
    </link>
    <!--sub-link defining coarse geometries of real robot's internal self-collision-->
    <link name="chin_link_12_sc">
        <collision>
            <origin rpy="0 0 0" xyz="0 0 0.0415" />
            <geometry>
                <cylinder length="0.083" radius="0.045" />
            </geometry>
        </collision>
        <collision>
            <origin xyz="0 0 0.083" />
            <geometry>
                <sphere radius="0.045" />
            </geometry>
        </collision>
        <collision>
            <origin xyz="0 0 0.0" />
            <geometry>
                <sphere radius="0.045" />
            </geometry>
        </collision>
        <inertial>
            <mass value="0.1" />
            <origin xyz="0 0 0" rpy="0 0 0" />
            <inertia ixx="0.03" iyy="0.03" izz="0.03" ixy="0.0" ixz="0.0" iyz="0.0" />
        </inertial>
    </link>
    <!--fixed joint between both sub-links-->
    <joint name="chin_link_12_sc_joint" type="fixed">
        <origin rpy="0 0 0" />
        <parent link="chin_link_12" />
        <child link="chin_link_12_sc" />
    </joint>
    <joint name="chin_joint_12" type="fixed">
        <origin rpy="-1.57079632679 0 0" xyz="0 0 0.087" />
        <parent link="chin_link_11" />
        <child link="chin_link_12" />
        <axis xyz="0 0 1" />
        <dynamics D="1" K="7000" damping="0.003" friction="0.0" mu_coulomb="0" mu_viscous="16" />
    </joint>
    <!--sub-link defining detailed meshes for collision with environment-->
    <link name="chin_link_13">
        <visual>
            <origin rpy="0 0 0" xyz="0 0 0.0385" />
            <geometry>
                <cylinder length="0.077" radius="0.045" />
            </geometry>
            <material name="silver" />
        </visual>
        <collision>
            <origin rpy="0 0 0" xyz="0 0 0.0385" />
            <geometry>
                <cylinder length="0.077" radius="0.045" />
            </geometry>
        </collision>
        <inertial>
            <mass value="0.1" />
            <origin xyz="0 0 0" rpy="0 0 0" />
            <inertia ixx="0.03" iyy="0.03" izz="0.03" ixy="0.0" ixz="0.0" iyz="0.0" />
        </inertial>
    </link>
    <!--sub-link defining coarse geometries of real robot's internal self-collision-->
    <link name="chin_link_13_sc">
        <collision>
            <origin rpy="0 0 0" xyz="0 0 0.0385" />
            <geometry>
                <cylinder length="0.077" radius="0.045" />
            </geometry>
        </collision>
        <collision>
            <origin xyz="0 0 0.077" />
            <geometry>
                <sphere radius="0.045" />
            </geometry>
        </collision>
        <collision>
            <origin xyz="0 0 0.0" />
            <geometry>
                <sphere radius="0.045" />
            </geometry>
        </collision>
        <inertial>
            <mass value="0.1" />
            <origin xyz="0 0 0" rpy="0 0 0" />
            <inertia ixx="0.03" iyy="0.03" izz="0.03" ixy="0.0" ixz="0.0" iyz="0.0" />
        </inertial>
    </link>
    <!--fixed joint between both sub-links-->
    <joint name="chin_link_13_sc_joint" type="fixed">
        <origin rpy="0 0 0" />
        <parent link="chin_link_13" />
        <child link="chin_link_13_sc" />
    </joint>
    <joint name="chin_joint_13" type="revolute">
        <safety_controller k_position="100.0" k_velocity="40.0" soft_lower_limit="-3.14159265359" soft_upper_limit="3.14159265359" />
        <origin rpy="0 0 0" xyz="0 0 0.083" />
        <parent link="chin_link_12" />
        <child link="chin_link_13" />
        <axis xyz="0 0 1" />
        <limit effort="0" lower="-3.14159265359" upper="3.14159265359" velocity="0" />
        <dynamics D="1" K="7000" damping="0.003" friction="0.0" mu_coulomb="0" mu_viscous="16" />
    </joint>
    <!--link14 to link13-->
    <link name="chin_link_14" />
    <joint name="chin_joint_14" type="fixed">
        <origin rpy="0 0 -3.14159265359" xyz="0 0 0.077" />
        <parent link="chin_link_13" />
        <child link="chin_link_14" />
    </joint>
    <transmission name="trans_chin_joint_1">
        <type>transmission_interface/SimpleTransmission</type>
        <joint name="chin_joint_1">
            <hardwareInterface>hardware_interface/EffortJointInterface</hardwareInterface>
        </joint>
        <actuator name="chin_joint_1_motor">
            <hardwareInterface>hardware_interface/EffortJointInterface</hardwareInterface>
            <mechanicalReduction>1</mechanicalReduction>
        </actuator>
    </transmission>
    <transmission name="trans_chin_joint_3">
        <type>transmission_interface/SimpleTransmission</type>
        <joint name="chin_joint_3">
            <hardwareInterface>hardware_interface/EffortJointInterface</hardwareInterface>
        </joint>
        <actuator name="chin_joint_3_motor">
            <hardwareInterface>hardware_interface/EffortJointInterface</hardwareInterface>
            <mechanicalReduction>1</mechanicalReduction>
        </actuator>
    </transmission>
    <transmission name="trans_chin_joint_6">
        <type>transmission_interface/SimpleTransmission</type>
        <joint name="chin_joint_6">
            <hardwareInterface>hardware_interface/EffortJointInterface</hardwareInterface>
        </joint>
        <actuator name="chin_joint_6_motor">
            <hardwareInterface>hardware_interface/EffortJointInterface</hardwareInterface>
            <mechanicalReduction>1</mechanicalReduction>
        </actuator>
    </transmission>
    <transmission name="trans_chin_joint_9">
        <type>transmission_interface/SimpleTransmission</type>
        <joint name="chin_joint_9">
            <hardwareInterface>hardware_interface/EffortJointInterface</hardwareInterface>
        </joint>
        <actuator name="chin_joint_9_motor">
            <hardwareInterface>hardware_interface/EffortJointInterface</hardwareInterface>
            <mechanicalReduction>1</mechanicalReduction>
        </actuator>
    </transmission>
    <transmission name="trans_chin_joint_11">
        <type>transmission_interface/SimpleTransmission</type>
        <joint name="chin_joint_11">
            <hardwareInterface>hardware_interface/EffortJointInterface</hardwareInterface>
        </joint>
        <actuator name="chin_joint_11_motor">
            <hardwareInterface>hardware_interface/EffortJointInterface</hardwareInterface>
            <mechanicalReduction>1</mechanicalReduction>
        </actuator>
    </transmission>
    <transmission name="trans_chin_joint_13">
        <type>transmission_interface/SimpleTransmission</type>
        <joint name="chin_joint_13">
            <hardwareInterface>hardware_interface/EffortJointInterface</hardwareInterface>
        </joint>
        <actuator name="chin_joint_13_motor">
            <hardwareInterface>hardware_interface/EffortJointInterface</hardwareInterface>
            <mechanicalReduction>1</mechanicalReduction>
        </actuator>
    </transmission>
    <gazebo>
        <plugin name="gazebo_ros_control">
            <robotNamespace>/</robotNamespace>
        </plugin>
    </gazebo>
</robot>

