<?xml version="1.0" encoding="utf-8" ?>
<!-- =================================================================================== -->
<!-- |    This document was autogenerated by xacro from /home/whi/catkin_workspace/src/chin_arm/chin_description/urdf/chin_arm.urdf.xacro | -->
<!-- |    EDITING THIS FILE BY HAND IS NOT RECOMMENDED                                 | -->
<!-- =================================================================================== -->
<robot name="chin_arm">
    <material name="white">
        <color rgba="1 1 1 1" />
    </material>
    <material name="blue">
        <color rgba="0 0 0.8 1" />
    </material>
    <material name="silver">
        <color rgba="0.51 0.54 0.59 1" />
    </material>
    <!--sub-link defining detailed meshes for collision with environment-->
    <link name="chin_link0">
        <visual>
            <origin rpy="0 0 0" xyz="0 0 0.102" />
            <geometry>
                <cylinder length="0.204" radius="0.095" />
            </geometry>
            <material name="black" />
        </visual>
        <collision>
            <origin rpy="0 0 0" xyz="0 0 0.102" />
            <geometry>
                <cylinder length="0.204" radius="0.095" />
            </geometry>
        </collision>
        <inertial>
            <mass value="0.1" />
            <origin xyz="0 0 0" rpy="0 0 0" />
            <inertia ixx="0.03" iyy="0.03" izz="0.03" ixy="0.0" ixz="0.0" iyz="0.0" />
        </inertial>
    </link>
    <!--sub-link defining coarse geometries of real robot's internal self-collision-->
    <link name="chin_link0_sc" />
    <!--fixed joint between both sub-links-->
    <joint name="chin_link0_sc_joint" type="fixed">
        <origin rpy="0 0 0" />
        <parent link="chin_link0" />
        <child link="chin_link0_sc" />
    </joint>
    <!--sub-link defining detailed meshes for collision with environment-->
    <link name="chin_link1">
        <visual>
            <origin rpy="0 0 0" xyz="0 0 0.0405" />
            <geometry>
                <cylinder length="0.081" radius="0.066" />
            </geometry>
            <material name="white" />
        </visual>
        <collision>
            <origin rpy="0 0 0" xyz="0 0 0.0405" />
            <geometry>
                <cylinder length="0.081" radius="0.066" />
            </geometry>
        </collision>
        <inertial>
            <mass value="0.1" />
            <origin xyz="0 0 0" rpy="0 0 0" />
            <inertia ixx="0.03" iyy="0.03" izz="0.03" ixy="0.0" ixz="0.0" iyz="0.0" />
        </inertial>
    </link>
    <!--sub-link defining coarse geometries of real robot's internal self-collision-->
    <link name="chin_link1_sc">
        <collision>
            <origin rpy="0 0 0" xyz="0 0 0.0405" />
            <geometry>
                <cylinder length="0.081" radius="0.066" />
            </geometry>
        </collision>
        <collision>
            <origin xyz="0 0 0.081" />
            <geometry>
                <sphere radius="0.066" />
            </geometry>
        </collision>
        <collision>
            <origin xyz="0 0 0.0" />
            <geometry>
                <sphere radius="0.066" />
            </geometry>
        </collision>
        <inertial>
            <mass value="0.1" />
            <origin xyz="0 0 0" rpy="0 0 0" />
            <inertia ixx="0.03" iyy="0.03" izz="0.03" ixy="0.0" ixz="0.0" iyz="0.0" />
        </inertial>
    </link>
    <!--fixed joint between both sub-links-->
    <joint name="chin_link1_sc_joint" type="fixed">
        <origin rpy="0 0 0" />
        <parent link="chin_link1" />
        <child link="chin_link1_sc" />
    </joint>
    <joint name="chin_joint1" type="revolute">
        <safety_controller k_position="100.0" k_velocity="40.0" soft_lower_limit="-3.14159265359" soft_upper_limit="3.14159265359" />
        <origin rpy="0 0 0" xyz="0 0 0.204" />
        <parent link="chin_link0" />
        <child link="chin_link1" />
        <axis xyz="0 0 1" />
        <limit effort="0" lower="-3.14159265359" upper="3.14159265359" velocity="0" />
        <dynamics D="1" K="7000" damping="0.003" friction="0.0" mu_coulomb="0" mu_viscous="16" />
    </joint>
    <!--sub-link defining detailed meshes for collision with environment-->
    <link name="chin_link2">
        <visual>
            <origin rpy="0 0 0" xyz="0 0 0.041" />
            <geometry>
                <cylinder length="0.082" radius="0.066" />
            </geometry>
            <material name="white" />
        </visual>
        <collision>
            <origin rpy="0 0 0" xyz="0 0 0.041" />
            <geometry>
                <cylinder length="0.082" radius="0.066" />
            </geometry>
        </collision>
        <inertial>
            <mass value="0.1" />
            <origin xyz="0 0 0" rpy="0 0 0" />
            <inertia ixx="0.03" iyy="0.03" izz="0.03" ixy="0.0" ixz="0.0" iyz="0.0" />
        </inertial>
    </link>
    <!--sub-link defining coarse geometries of real robot's internal self-collision-->
    <link name="chin_link2_sc">
        <collision>
            <origin rpy="0 0 0" xyz="0 0 0.041" />
            <geometry>
                <cylinder length="0.082" radius="0.066" />
            </geometry>
        </collision>
        <collision>
            <origin xyz="0 0 0.082" />
            <geometry>
                <sphere radius="0.066" />
            </geometry>
        </collision>
        <collision>
            <origin xyz="0 0 0.0" />
            <geometry>
                <sphere radius="0.066" />
            </geometry>
        </collision>
        <inertial>
            <mass value="0.1" />
            <origin xyz="0 0 0" rpy="0 0 0" />
            <inertia ixx="0.03" iyy="0.03" izz="0.03" ixy="0.0" ixz="0.0" iyz="0.0" />
        </inertial>
    </link>
    <!--fixed joint between both sub-links-->
    <joint name="chin_link2_sc_joint" type="fixed">
        <origin rpy="0 0 0" />
        <parent link="chin_link2" />
        <child link="chin_link2_sc" />
    </joint>
    <joint name="chin_joint2" type="fixed">
        <origin rpy="-1.57079632679 0 0" xyz="0 0 0.081" />
        <parent link="chin_link1" />
        <child link="chin_link2" />
        <axis xyz="0 0 1" />
        <dynamics D="1" K="7000" damping="0.003" friction="0.0" mu_coulomb="0" mu_viscous="16" />
    </joint>
    <!--sub-link defining detailed meshes for collision with environment-->
    <link name="chin_link3">
        <visual>
            <origin rpy="0 0 0" xyz="0 0 0.035" />
            <geometry>
                <cylinder length="0.07" radius="0.066" />
            </geometry>
            <material name="white" />
        </visual>
        <collision>
            <origin rpy="0 0 0" xyz="0 0 0.035" />
            <geometry>
                <cylinder length="0.07" radius="0.066" />
            </geometry>
        </collision>
        <inertial>
            <mass value="0.1" />
            <origin xyz="0 0 0" rpy="0 0 0" />
            <inertia ixx="0.03" iyy="0.03" izz="0.03" ixy="0.0" ixz="0.0" iyz="0.0" />
        </inertial>
    </link>
    <!--sub-link defining coarse geometries of real robot's internal self-collision-->
    <link name="chin_link3_sc">
        <collision>
            <origin rpy="0 0 0" xyz="0 0 0.035" />
            <geometry>
                <cylinder length="0.07" radius="0.066" />
            </geometry>
        </collision>
        <collision>
            <origin xyz="0 0 0.07" />
            <geometry>
                <sphere radius="0.066" />
            </geometry>
        </collision>
        <collision>
            <origin xyz="0 0 0.0" />
            <geometry>
                <sphere radius="0.066" />
            </geometry>
        </collision>
        <inertial>
            <mass value="0.1" />
            <origin xyz="0 0 0" rpy="0 0 0" />
            <inertia ixx="0.03" iyy="0.03" izz="0.03" ixy="0.0" ixz="0.0" iyz="0.0" />
        </inertial>
    </link>
    <!--fixed joint between both sub-links-->
    <joint name="chin_link3_sc_joint" type="fixed">
        <origin rpy="0 0 0" />
        <parent link="chin_link3" />
        <child link="chin_link3_sc" />
    </joint>
    <joint name="chin_joint3" type="revolute">
        <safety_controller k_position="100.0" k_velocity="40.0" soft_lower_limit="-3.14159265359" soft_upper_limit="3.14159265359" />
        <origin rpy="0 0 0" xyz="0 0 0.082" />
        <parent link="chin_link2" />
        <child link="chin_link3" />
        <axis xyz="0 0 1" />
        <limit effort="0" lower="-3.14159265359" upper="3.14159265359" velocity="0" />
        <dynamics D="1" K="7000" damping="0.003" friction="0.0" mu_coulomb="0" mu_viscous="16" />
    </joint>
    <!--sub-link defining detailed meshes for collision with environment-->
    <link name="chin_link4">
        <visual>
            <origin rpy="0 0 0" xyz="0 0 0.199" />
            <geometry>
                <cylinder length="0.398" radius="0.055" />
            </geometry>
            <material name="white" />
        </visual>
        <collision>
            <origin rpy="0 0 0" xyz="0 0 0.199" />
            <geometry>
                <cylinder length="0.398" radius="0.055" />
            </geometry>
        </collision>
        <inertial>
            <mass value="0.1" />
            <origin xyz="0 0 0" rpy="0 0 0" />
            <inertia ixx="0.03" iyy="0.03" izz="0.03" ixy="0.0" ixz="0.0" iyz="0.0" />
        </inertial>
    </link>
    <!--sub-link defining coarse geometries of real robot's internal self-collision-->
    <link name="chin_link4_sc">
        <collision>
            <origin rpy="0 0 0" xyz="0 0 0.199" />
            <geometry>
                <cylinder length="0.398" radius="0.055" />
            </geometry>
        </collision>
        <collision>
            <origin xyz="0 0 0.398" />
            <geometry>
                <sphere radius="0.055" />
            </geometry>
        </collision>
        <collision>
            <origin xyz="0 0 0.0" />
            <geometry>
                <sphere radius="0.055" />
            </geometry>
        </collision>
        <inertial>
            <mass value="0.1" />
            <origin xyz="0 0 0" rpy="0 0 0" />
            <inertia ixx="0.03" iyy="0.03" izz="0.03" ixy="0.0" ixz="0.0" iyz="0.0" />
        </inertial>
    </link>
    <!--fixed joint between both sub-links-->
    <joint name="chin_link4_sc_joint" type="fixed">
        <origin rpy="0 0 0" />
        <parent link="chin_link4" />
        <child link="chin_link4_sc" />
    </joint>
    <joint name="chin_joint4" type="fixed">
        <origin rpy="1.57079632679 0 0" xyz="0 0 0.07" />
        <parent link="chin_link3" />
        <child link="chin_link4" />
        <axis xyz="0 0 1" />
        <dynamics D="1" K="7000" damping="0.003" friction="0.0" mu_coulomb="0" mu_viscous="16" />
    </joint>
    <!--sub-link defining detailed meshes for collision with environment-->
    <link name="chin_link5">
        <visual>
            <origin rpy="0 0 0" xyz="0 0 0.0325" />
            <geometry>
                <cylinder length="0.065" radius="0.055" />
            </geometry>
            <material name="white" />
        </visual>
        <collision>
            <origin rpy="0 0 0" xyz="0 0 0.0325" />
            <geometry>
                <cylinder length="0.065" radius="0.055" />
            </geometry>
        </collision>
        <inertial>
            <mass value="0.1" />
            <origin xyz="0 0 0" rpy="0 0 0" />
            <inertia ixx="0.03" iyy="0.03" izz="0.03" ixy="0.0" ixz="0.0" iyz="0.0" />
        </inertial>
    </link>
    <!--sub-link defining coarse geometries of real robot's internal self-collision-->
    <link name="chin_link5_sc">
        <collision>
            <origin rpy="0 0 0" xyz="0 0 0.0325" />
            <geometry>
                <cylinder length="0.065" radius="0.055" />
            </geometry>
        </collision>
        <collision>
            <origin xyz="0 0 0.065" />
            <geometry>
                <sphere radius="0.055" />
            </geometry>
        </collision>
        <collision>
            <origin xyz="0 0 0.0" />
            <geometry>
                <sphere radius="0.055" />
            </geometry>
        </collision>
        <inertial>
            <mass value="0.1" />
            <origin xyz="0 0 0" rpy="0 0 0" />
            <inertia ixx="0.03" iyy="0.03" izz="0.03" ixy="0.0" ixz="0.0" iyz="0.0" />
        </inertial>
    </link>
    <!--fixed joint between both sub-links-->
    <joint name="chin_link5_sc_joint" type="fixed">
        <origin rpy="0 0 0" />
        <parent link="chin_link5" />
        <child link="chin_link5_sc" />
    </joint>
    <joint name="chin_joint5" type="fixed">
        <origin rpy="1.57079632679 0 0" xyz="0 0 0.398" />
        <parent link="chin_link4" />
        <child link="chin_link5" />
        <axis xyz="0 0 1" />
        <dynamics D="1" K="7000" damping="0.003" friction="0.0" mu_coulomb="0" mu_viscous="16" />
    </joint>
    <!--sub-link defining detailed meshes for collision with environment-->
    <link name="chin_link6">
        <visual>
            <origin rpy="0 0 0" xyz="0 0 0.0315" />
            <geometry>
                <cylinder length="0.063" radius="0.055" />
            </geometry>
            <material name="white" />
        </visual>
        <collision>
            <origin rpy="0 0 0" xyz="0 0 0.0315" />
            <geometry>
                <cylinder length="0.063" radius="0.055" />
            </geometry>
        </collision>
        <inertial>
            <mass value="0.1" />
            <origin xyz="0 0 0" rpy="0 0 0" />
            <inertia ixx="0.03" iyy="0.03" izz="0.03" ixy="0.0" ixz="0.0" iyz="0.0" />
        </inertial>
    </link>
    <!--sub-link defining coarse geometries of real robot's internal self-collision-->
    <link name="chin_link6_sc">
        <collision>
            <origin rpy="0 0 0" xyz="0 0 0.0315" />
            <geometry>
                <cylinder length="0.063" radius="0.055" />
            </geometry>
        </collision>
        <collision>
            <origin xyz="0 0 0.063" />
            <geometry>
                <sphere radius="0.055" />
            </geometry>
        </collision>
        <collision>
            <origin xyz="0 0 0.0" />
            <geometry>
                <sphere radius="0.055" />
            </geometry>
        </collision>
        <inertial>
            <mass value="0.1" />
            <origin xyz="0 0 0" rpy="0 0 0" />
            <inertia ixx="0.03" iyy="0.03" izz="0.03" ixy="0.0" ixz="0.0" iyz="0.0" />
        </inertial>
    </link>
    <!--fixed joint between both sub-links-->
    <joint name="chin_link6_sc_joint" type="fixed">
        <origin rpy="0 0 0" />
        <parent link="chin_link6" />
        <child link="chin_link6_sc" />
    </joint>
    <joint name="chin_joint6" type="revolute">
        <safety_controller k_position="100.0" k_velocity="40.0" soft_lower_limit="-2.7925" soft_upper_limit="2.7925" />
        <origin rpy="0 0 0" xyz="0 0 0.065" />
        <parent link="chin_link5" />
        <child link="chin_link6" />
        <axis xyz="0 0 1" />
        <limit effort="0" lower="-2.7925" upper="2.7925" velocity="0" />
        <dynamics D="1" K="7000" damping="0.003" friction="0.0" mu_coulomb="0" mu_viscous="16" />
    </joint>
    <!--sub-link defining detailed meshes for collision with environment-->
    <link name="chin_link7">
        <visual>
            <origin rpy="0 0 0" xyz="0 0 0.18" />
            <geometry>
                <cylinder length="0.36" radius="0.045" />
            </geometry>
            <material name="white" />
        </visual>
        <collision>
            <origin rpy="0 0 0" xyz="0 0 0.18" />
            <geometry>
                <cylinder length="0.36" radius="0.045" />
            </geometry>
        </collision>
        <inertial>
            <mass value="0.1" />
            <origin xyz="0 0 0" rpy="0 0 0" />
            <inertia ixx="0.03" iyy="0.03" izz="0.03" ixy="0.0" ixz="0.0" iyz="0.0" />
        </inertial>
    </link>
    <!--sub-link defining coarse geometries of real robot's internal self-collision-->
    <link name="chin_link7_sc">
        <collision>
            <origin rpy="0 0 0" xyz="0 0 0.18" />
            <geometry>
                <cylinder length="0.36" radius="0.045" />
            </geometry>
        </collision>
        <collision>
            <origin xyz="0 0 0.36" />
            <geometry>
                <sphere radius="0.045" />
            </geometry>
        </collision>
        <collision>
            <origin xyz="0 0 0.0" />
            <geometry>
                <sphere radius="0.045" />
            </geometry>
        </collision>
        <inertial>
            <mass value="0.1" />
            <origin xyz="0 0 0" rpy="0 0 0" />
            <inertia ixx="0.03" iyy="0.03" izz="0.03" ixy="0.0" ixz="0.0" iyz="0.0" />
        </inertial>
    </link>
    <!--fixed joint between both sub-links-->
    <joint name="chin_link7_sc_joint" type="fixed">
        <origin rpy="0 0 0" />
        <parent link="chin_link7" />
        <child link="chin_link7_sc" />
    </joint>
    <joint name="chin_joint7" type="fixed">
        <origin rpy="-1.57079632679 0 0" xyz="0 0 0.063" />
        <parent link="chin_link6" />
        <child link="chin_link7" />
        <axis xyz="0 0 1" />
        <dynamics D="1" K="7000" damping="0.003" friction="0.0" mu_coulomb="0" mu_viscous="16" />
    </joint>
    <!--sub-link defining detailed meshes for collision with environment-->
    <link name="chin_link8">
        <visual>
            <origin rpy="0 0 0" xyz="0 0 0.0415" />
            <geometry>
                <cylinder length="0.083" radius="0.045" />
            </geometry>
            <material name="white" />
        </visual>
        <collision>
            <origin rpy="0 0 0" xyz="0 0 0.0415" />
            <geometry>
                <cylinder length="0.083" radius="0.045" />
            </geometry>
        </collision>
        <inertial>
            <mass value="0.1" />
            <origin xyz="0 0 0" rpy="0 0 0" />
            <inertia ixx="0.03" iyy="0.03" izz="0.03" ixy="0.0" ixz="0.0" iyz="0.0" />
        </inertial>
    </link>
    <!--sub-link defining coarse geometries of real robot's internal self-collision-->
    <link name="chin_link8_sc">
        <collision>
            <origin rpy="0 0 0" xyz="0 0 0.0415" />
            <geometry>
                <cylinder length="0.083" radius="0.045" />
            </geometry>
        </collision>
        <collision>
            <origin xyz="0 0 0.083" />
            <geometry>
                <sphere radius="0.045" />
            </geometry>
        </collision>
        <collision>
            <origin xyz="0 0 0.0" />
            <geometry>
                <sphere radius="0.045" />
            </geometry>
        </collision>
        <inertial>
            <mass value="0.1" />
            <origin xyz="0 0 0" rpy="0 0 0" />
            <inertia ixx="0.03" iyy="0.03" izz="0.03" ixy="0.0" ixz="0.0" iyz="0.0" />
        </inertial>
    </link>
    <!--fixed joint between both sub-links-->
    <joint name="chin_link8_sc_joint" type="fixed">
        <origin rpy="0 0 0" />
        <parent link="chin_link8" />
        <child link="chin_link8_sc" />
    </joint>
    <joint name="chin_joint8" type="fixed">
        <origin rpy="-1.57079632679 0 0" xyz="0 0 0.36" />
        <parent link="chin_link7" />
        <child link="chin_link8" />
        <axis xyz="0 0 1" />
        <dynamics D="1" K="7000" damping="0.003" friction="0.0" mu_coulomb="0" mu_viscous="16" />
    </joint>
    <!--sub-link defining detailed meshes for collision with environment-->
    <link name="chin_link9">
        <visual>
            <origin rpy="0 0 0" xyz="0 0 0.0435" />
            <geometry>
                <cylinder length="0.087" radius="0.045" />
            </geometry>
            <material name="white" />
        </visual>
        <collision>
            <origin rpy="0 0 0" xyz="0 0 0.0435" />
            <geometry>
                <cylinder length="0.087" radius="0.045" />
            </geometry>
        </collision>
        <inertial>
            <mass value="0.1" />
            <origin xyz="0 0 0" rpy="0 0 0" />
            <inertia ixx="0.03" iyy="0.03" izz="0.03" ixy="0.0" ixz="0.0" iyz="0.0" />
        </inertial>
    </link>
    <!--sub-link defining coarse geometries of real robot's internal self-collision-->
    <link name="chin_link9_sc">
        <collision>
            <origin rpy="0 0 0" xyz="0 0 0.0435" />
            <geometry>
                <cylinder length="0.087" radius="0.045" />
            </geometry>
        </collision>
        <collision>
            <origin xyz="0 0 0.087" />
            <geometry>
                <sphere radius="0.045" />
            </geometry>
        </collision>
        <collision>
            <origin xyz="0 0 0.0" />
            <geometry>
                <sphere radius="0.045" />
            </geometry>
        </collision>
        <inertial>
            <mass value="0.1" />
            <origin xyz="0 0 0" rpy="0 0 0" />
            <inertia ixx="0.03" iyy="0.03" izz="0.03" ixy="0.0" ixz="0.0" iyz="0.0" />
        </inertial>
    </link>
    <!--fixed joint between both sub-links-->
    <joint name="chin_link9_sc_joint" type="fixed">
        <origin rpy="0 0 0" />
        <parent link="chin_link9" />
        <child link="chin_link9_sc" />
    </joint>
    <joint name="chin_joint9" type="revolute">
        <safety_controller k_position="100.0" k_velocity="40.0" soft_lower_limit="-3.14159265359" soft_upper_limit="3.14159265359" />
        <origin rpy="0 0 0" xyz="0 0 0.083" />
        <parent link="chin_link8" />
        <child link="chin_link9" />
        <axis xyz="0 0 1" />
        <limit effort="0" lower="-3.14159265359" upper="3.14159265359" velocity="0" />
        <dynamics D="1" K="7000" damping="0.003" friction="0.0" mu_coulomb="0" mu_viscous="16" />
    </joint>
    <!--sub-link defining detailed meshes for collision with environment-->
    <link name="chin_link10">
        <visual>
            <origin rpy="0 0 0" xyz="0 0 0.0415" />
            <geometry>
                <cylinder length="0.083" radius="0.045" />
            </geometry>
            <material name="white" />
        </visual>
        <collision>
            <origin rpy="0 0 0" xyz="0 0 0.0415" />
            <geometry>
                <cylinder length="0.083" radius="0.045" />
            </geometry>
        </collision>
        <inertial>
            <mass value="0.1" />
            <origin xyz="0 0 0" rpy="0 0 0" />
            <inertia ixx="0.03" iyy="0.03" izz="0.03" ixy="0.0" ixz="0.0" iyz="0.0" />
        </inertial>
    </link>
    <!--sub-link defining coarse geometries of real robot's internal self-collision-->
    <link name="chin_link10_sc">
        <collision>
            <origin rpy="0 0 0" xyz="0 0 0.0415" />
            <geometry>
                <cylinder length="0.083" radius="0.045" />
            </geometry>
        </collision>
        <collision>
            <origin xyz="0 0 0.083" />
            <geometry>
                <sphere radius="0.045" />
            </geometry>
        </collision>
        <collision>
            <origin xyz="0 0 0.0" />
            <geometry>
                <sphere radius="0.045" />
            </geometry>
        </collision>
        <inertial>
            <mass value="0.1" />
            <origin xyz="0 0 0" rpy="0 0 0" />
            <inertia ixx="0.03" iyy="0.03" izz="0.03" ixy="0.0" ixz="0.0" iyz="0.0" />
        </inertial>
    </link>
    <!--fixed joint between both sub-links-->
    <joint name="chin_link10_sc_joint" type="fixed">
        <origin rpy="0 0 0" />
        <parent link="chin_link10" />
        <child link="chin_link10_sc" />
    </joint>
    <joint name="chin_joint10" type="fixed">
        <origin rpy="1.57079632679 0 0" xyz="0 0 0.087" />
        <parent link="chin_link9" />
        <child link="chin_link10" />
        <axis xyz="0 0 1" />
        <dynamics D="1" K="7000" damping="0.003" friction="0.0" mu_coulomb="0" mu_viscous="16" />
    </joint>
    <!--sub-link defining detailed meshes for collision with environment-->
    <link name="chin_link11">
        <visual>
            <origin rpy="0 0 0" xyz="0 0 0.0435" />
            <geometry>
                <cylinder length="0.087" radius="0.045" />
            </geometry>
            <material name="white" />
        </visual>
        <collision>
            <origin rpy="0 0 0" xyz="0 0 0.0435" />
            <geometry>
                <cylinder length="0.087" radius="0.045" />
            </geometry>
        </collision>
        <inertial>
            <mass value="0.1" />
            <origin xyz="0 0 0" rpy="0 0 0" />
            <inertia ixx="0.03" iyy="0.03" izz="0.03" ixy="0.0" ixz="0.0" iyz="0.0" />
        </inertial>
    </link>
    <!--sub-link defining coarse geometries of real robot's internal self-collision-->
    <link name="chin_link11_sc">
        <collision>
            <origin rpy="0 0 0" xyz="0 0 0.0435" />
            <geometry>
                <cylinder length="0.087" radius="0.045" />
            </geometry>
        </collision>
        <collision>
            <origin xyz="0 0 0.087" />
            <geometry>
                <sphere radius="0.045" />
            </geometry>
        </collision>
        <collision>
            <origin xyz="0 0 0.0" />
            <geometry>
                <sphere radius="0.045" />
            </geometry>
        </collision>
        <inertial>
            <mass value="0.1" />
            <origin xyz="0 0 0" rpy="0 0 0" />
            <inertia ixx="0.03" iyy="0.03" izz="0.03" ixy="0.0" ixz="0.0" iyz="0.0" />
        </inertial>
    </link>
    <!--fixed joint between both sub-links-->
    <joint name="chin_link11_sc_joint" type="fixed">
        <origin rpy="0 0 0" />
        <parent link="chin_link11" />
        <child link="chin_link11_sc" />
    </joint>
    <joint name="chin_joint11" type="revolute">
        <safety_controller k_position="100.0" k_velocity="40.0" soft_lower_limit="-3.14159265359" soft_upper_limit="3.14159265359" />
        <origin rpy="0 0 0" xyz="0 0 0.083" />
        <parent link="chin_link10" />
        <child link="chin_link11" />
        <axis xyz="0 0 1" />
        <limit effort="0" lower="-3.14159265359" upper="3.14159265359" velocity="0" />
        <dynamics D="1" K="7000" damping="0.003" friction="0.0" mu_coulomb="0" mu_viscous="16" />
    </joint>
    <!--sub-link defining detailed meshes for collision with environment-->
    <link name="chin_link12">
        <visual>
            <origin rpy="0 0 0" xyz="0 0 0.0415" />
            <geometry>
                <cylinder length="0.083" radius="0.045" />
            </geometry>
            <material name="white" />
        </visual>
        <collision>
            <origin rpy="0 0 0" xyz="0 0 0.0415" />
            <geometry>
                <cylinder length="0.083" radius="0.045" />
            </geometry>
        </collision>
        <inertial>
            <mass value="0.1" />
            <origin xyz="0 0 0" rpy="0 0 0" />
            <inertia ixx="0.03" iyy="0.03" izz="0.03" ixy="0.0" ixz="0.0" iyz="0.0" />
        </inertial>
    </link>
    <!--sub-link defining coarse geometries of real robot's internal self-collision-->
    <link name="chin_link12_sc">
        <collision>
            <origin rpy="0 0 0" xyz="0 0 0.0415" />
            <geometry>
                <cylinder length="0.083" radius="0.045" />
            </geometry>
        </collision>
        <collision>
            <origin xyz="0 0 0.083" />
            <geometry>
                <sphere radius="0.045" />
            </geometry>
        </collision>
        <collision>
            <origin xyz="0 0 0.0" />
            <geometry>
                <sphere radius="0.045" />
            </geometry>
        </collision>
        <inertial>
            <mass value="0.1" />
            <origin xyz="0 0 0" rpy="0 0 0" />
            <inertia ixx="0.03" iyy="0.03" izz="0.03" ixy="0.0" ixz="0.0" iyz="0.0" />
        </inertial>
    </link>
    <!--fixed joint between both sub-links-->
    <joint name="chin_link12_sc_joint" type="fixed">
        <origin rpy="0 0 0" />
        <parent link="chin_link12" />
        <child link="chin_link12_sc" />
    </joint>
    <joint name="chin_joint12" type="fixed">
        <origin rpy="-1.57079632679 0 0" xyz="0 0 0.087" />
        <parent link="chin_link11" />
        <child link="chin_link12" />
        <axis xyz="0 0 1" />
        <dynamics D="1" K="7000" damping="0.003" friction="0.0" mu_coulomb="0" mu_viscous="16" />
    </joint>
    <!--sub-link defining detailed meshes for collision with environment-->
    <link name="chin_link13">
        <visual>
            <origin rpy="0 0 0" xyz="0 0 0.0385" />
            <geometry>
                <cylinder length="0.077" radius="0.045" />
            </geometry>
            <material name="silver" />
        </visual>
        <collision>
            <origin rpy="0 0 0" xyz="0 0 0.0385" />
            <geometry>
                <cylinder length="0.077" radius="0.045" />
            </geometry>
        </collision>
        <inertial>
            <mass value="0.1" />
            <origin xyz="0 0 0" rpy="0 0 0" />
            <inertia ixx="0.03" iyy="0.03" izz="0.03" ixy="0.0" ixz="0.0" iyz="0.0" />
        </inertial>
    </link>
    <!--sub-link defining coarse geometries of real robot's internal self-collision-->
    <link name="chin_link13_sc">
        <collision>
            <origin rpy="0 0 0" xyz="0 0 0.0385" />
            <geometry>
                <cylinder length="0.077" radius="0.045" />
            </geometry>
        </collision>
        <collision>
            <origin xyz="0 0 0.077" />
            <geometry>
                <sphere radius="0.045" />
            </geometry>
        </collision>
        <collision>
            <origin xyz="0 0 0.0" />
            <geometry>
                <sphere radius="0.045" />
            </geometry>
        </collision>
        <inertial>
            <mass value="0.1" />
            <origin xyz="0 0 0" rpy="0 0 0" />
            <inertia ixx="0.03" iyy="0.03" izz="0.03" ixy="0.0" ixz="0.0" iyz="0.0" />
        </inertial>
    </link>
    <!--fixed joint between both sub-links-->
    <joint name="chin_link13_sc_joint" type="fixed">
        <origin rpy="0 0 0" />
        <parent link="chin_link13" />
        <child link="chin_link13_sc" />
    </joint>
    <joint name="chin_joint13" type="revolute">
        <safety_controller k_position="100.0" k_velocity="40.0" soft_lower_limit="-3.14159265359" soft_upper_limit="3.14159265359" />
        <origin rpy="0 0 0" xyz="0 0 0.083" />
        <parent link="chin_link12" />
        <child link="chin_link13" />
        <axis xyz="0 0 1" />
        <limit effort="0" lower="-3.14159265359" upper="3.14159265359" velocity="0" />
        <dynamics D="1" K="7000" damping="0.003" friction="0.0" mu_coulomb="0" mu_viscous="16" />
    </joint>
    <!--link14 to link13-->
    <link name="chin_link14" />
    <joint name="chin_joint14" type="fixed">
        <origin rpy="0 0 -3.14159265359" xyz="0 0 0.077" />
        <parent link="chin_link13" />
        <child link="chin_link14" />
    </joint>
    <transmission name="trans_chin_joint1">
        <type>transmission_interface/SimpleTransmission</type>
        <joint name="chin_joint1">
            <hardwareInterface>hardware_interface/EffortJointInterface</hardwareInterface>
        </joint>
        <actuator name="chin_joint1_motor">
            <hardwareInterface>hardware_interface/EffortJointInterface</hardwareInterface>
            <mechanicalReduction>1</mechanicalReduction>
        </actuator>
    </transmission>
    <transmission name="trans_chin_joint3">
        <type>transmission_interface/SimpleTransmission</type>
        <joint name="chin_joint3">
            <hardwareInterface>hardware_interface/EffortJointInterface</hardwareInterface>
        </joint>
        <actuator name="chin_joint3_motor">
            <hardwareInterface>hardware_interface/EffortJointInterface</hardwareInterface>
            <mechanicalReduction>1</mechanicalReduction>
        </actuator>
    </transmission>
    <transmission name="trans_chin_joint6">
        <type>transmission_interface/SimpleTransmission</type>
        <joint name="chin_joint6">
            <hardwareInterface>hardware_interface/EffortJointInterface</hardwareInterface>
        </joint>
        <actuator name="chin_joint6_motor">
            <hardwareInterface>hardware_interface/EffortJointInterface</hardwareInterface>
            <mechanicalReduction>1</mechanicalReduction>
        </actuator>
    </transmission>
    <transmission name="trans_chin_joint9">
        <type>transmission_interface/SimpleTransmission</type>
        <joint name="chin_joint9">
            <hardwareInterface>hardware_interface/EffortJointInterface</hardwareInterface>
        </joint>
        <actuator name="chin_joint9_motor">
            <hardwareInterface>hardware_interface/EffortJointInterface</hardwareInterface>
            <mechanicalReduction>1</mechanicalReduction>
        </actuator>
    </transmission>
    <transmission name="trans_chin_joint11">
        <type>transmission_interface/SimpleTransmission</type>
        <joint name="chin_joint11">
            <hardwareInterface>hardware_interface/EffortJointInterface</hardwareInterface>
        </joint>
        <actuator name="chin_joint11_motor">
            <hardwareInterface>hardware_interface/EffortJointInterface</hardwareInterface>
            <mechanicalReduction>1</mechanicalReduction>
        </actuator>
    </transmission>
    <transmission name="trans_chin_joint13">
        <type>transmission_interface/SimpleTransmission</type>
        <joint name="chin_joint13">
            <hardwareInterface>hardware_interface/EffortJointInterface</hardwareInterface>
        </joint>
        <actuator name="chin_joint13_motor">
            <hardwareInterface>hardware_interface/EffortJointInterface</hardwareInterface>
            <mechanicalReduction>1</mechanicalReduction>
        </actuator>
    </transmission>
    <gazebo>
        <plugin name="gazebo_ros_control">
            <robotNamespace>/</robotNamespace>
        </plugin>
    </gazebo>
</robot>

